Traceback (most recent call last):
  File "/home/yalloosb/server/passenger_wsgi.py", line 1, in <module>
    from demo.wsgi import application
  File "/home/yalloosb/server/demo/wsgi.py", line 16, in <module>
    application = get_wsgi_application()
  File "/home/yalloosb/virtualenv/server/3.8/lib/python3.8/site-packages/django/core/wsgi.py", line 12, in get_wsgi_application
    django.setup(set_prefix=False)
  File "/home/yalloosb/virtualenv/server/3.8/lib/python3.8/site-packages/django/__init__.py", line 24, in setup
    apps.populate(settings.INSTALLED_APPS)
  File "/home/yalloosb/virtualenv/server/3.8/lib/python3.8/site-packages/django/apps/registry.py", line 91, in populate
    app_config = AppConfig.create(entry)
  File "/home/yalloosb/virtualenv/server/3.8/lib/python3.8/site-packages/django/apps/config.py", line 223, in create
    import_module(entry)
  File "/home/yalloosb/virtualenv/server/3.8/lib64/python3.8/importlib/__init__.py", line 127, in import_module
    return _bootstrap._gcd_import(name[level:], package, level)
ModuleNotFoundError: No module named 'corsheaders'
Traceback (most recent call last):
  File "/home/yalloosb/server/passenger_wsgi.py", line 1, in <module>
    from demo.wsgi import application
  File "/home/yalloosb/server/demo/wsgi.py", line 16, in <module>
    application = get_wsgi_application()
  File "/home/yalloosb/virtualenv/server/3.8/lib/python3.8/site-packages/django/core/wsgi.py", line 12, in get_wsgi_application
    django.setup(set_prefix=False)
  File "/home/yalloosb/virtualenv/server/3.8/lib/python3.8/site-packages/django/__init__.py", line 24, in setup
    apps.populate(settings.INSTALLED_APPS)
  File "/home/yalloosb/virtualenv/server/3.8/lib/python3.8/site-packages/django/apps/registry.py", line 83, in populate
    raise RuntimeError("populate() isn't reentrant")
RuntimeError: populate() isn't reentrant
Traceback (most recent call last):
  File "/home/yalloosb/server/passenger_wsgi.py", line 1, in <module>
    from demo.wsgi import application
  File "/home/yalloosb/server/demo/wsgi.py", line 16, in <module>
    application = get_wsgi_application()
  File "/home/yalloosb/virtualenv/server/3.8/lib/python3.8/site-packages/django/core/wsgi.py", line 12, in get_wsgi_application
    django.setup(set_prefix=False)
  File "/home/yalloosb/virtualenv/server/3.8/lib/python3.8/site-packages/django/__init__.py", line 24, in setup
    apps.populate(settings.INSTALLED_APPS)
  File "/home/yalloosb/virtualenv/server/3.8/lib/python3.8/site-packages/django/apps/registry.py", line 91, in populate
    app_config = AppConfig.create(entry)
  File "/home/yalloosb/virtualenv/server/3.8/lib/python3.8/site-packages/django/apps/config.py", line 223, in create
    import_module(entry)
  File "/home/yalloosb/virtualenv/server/3.8/lib64/python3.8/importlib/__init__.py", line 127, in import_module
    return _bootstrap._gcd_import(name[level:], package, level)
ModuleNotFoundError: No module named 'corsheaders'
Traceback (most recent call last):
  File "/home/yalloosb/server/passenger_wsgi.py", line 1, in <module>
    from demo.wsgi import application
  File "/home/yalloosb/server/demo/wsgi.py", line 16, in <module>
    application = get_wsgi_application()
  File "/home/yalloosb/virtualenv/server/3.8/lib/python3.8/site-packages/django/core/wsgi.py", line 12, in get_wsgi_application
    django.setup(set_prefix=False)
  File "/home/yalloosb/virtualenv/server/3.8/lib/python3.8/site-packages/django/__init__.py", line 24, in setup
    apps.populate(settings.INSTALLED_APPS)
  File "/home/yalloosb/virtualenv/server/3.8/lib/python3.8/site-packages/django/apps/registry.py", line 83, in populate
    raise RuntimeError("populate() isn't reentrant")
RuntimeError: populate() isn't reentrant
Traceback (most recent call last):
  File "/home/yalloosb/server/passenger_wsgi.py", line 1, in <module>
    from demo.wsgi import application
  File "/home/yalloosb/server/demo/wsgi.py", line 16, in <module>
    application = get_wsgi_application()
  File "/home/yalloosb/virtualenv/server/3.8/lib/python3.8/site-packages/django/core/wsgi.py", line 12, in get_wsgi_application
    django.setup(set_prefix=False)
  File "/home/yalloosb/virtualenv/server/3.8/lib/python3.8/site-packages/django/__init__.py", line 24, in setup
    apps.populate(settings.INSTALLED_APPS)
  File "/home/yalloosb/virtualenv/server/3.8/lib/python3.8/site-packages/django/apps/registry.py", line 83, in populate
    raise RuntimeError("populate() isn't reentrant")
RuntimeError: populate() isn't reentrant
Traceback (most recent call last):
  File "/home/yalloosb/server/passenger_wsgi.py", line 1, in <module>
    from demo.wsgi import application
  File "/home/yalloosb/server/demo/wsgi.py", line 16, in <module>
    application = get_wsgi_application()
  File "/home/yalloosb/virtualenv/server/3.8/lib/python3.8/site-packages/django/core/wsgi.py", line 12, in get_wsgi_application
    django.setup(set_prefix=False)
  File "/home/yalloosb/virtualenv/server/3.8/lib/python3.8/site-packages/django/__init__.py", line 24, in setup
    apps.populate(settings.INSTALLED_APPS)
  File "/home/yalloosb/virtualenv/server/3.8/lib/python3.8/site-packages/django/apps/registry.py", line 83, in populate
    raise RuntimeError("populate() isn't reentrant")
RuntimeError: populate() isn't reentrant
Traceback (most recent call last):
  File "/home/yalloosb/server/passenger_wsgi.py", line 1, in <module>
    from demo.wsgi import application
  File "/home/yalloosb/server/demo/wsgi.py", line 16, in <module>
    application = get_wsgi_application()
  File "/home/yalloosb/virtualenv/server/3.8/lib/python3.8/site-packages/django/core/wsgi.py", line 12, in get_wsgi_application
    django.setup(set_prefix=False)
  File "/home/yalloosb/virtualenv/server/3.8/lib/python3.8/site-packages/django/__init__.py", line 24, in setup
    apps.populate(settings.INSTALLED_APPS)
  File "/home/yalloosb/virtualenv/server/3.8/lib/python3.8/site-packages/django/apps/registry.py", line 83, in populate
    raise RuntimeError("populate() isn't reentrant")
RuntimeError: populate() isn't reentrant
Traceback (most recent call last):
  File "/home/yalloosb/virtualenv/server/3.8/lib/python3.8/site-packages/django/db/backends/mysql/base.py", line 15, in <module>
    import MySQLdb as Database
ModuleNotFoundError: No module named 'MySQLdb'

The above exception was the direct cause of the following exception:

Traceback (most recent call last):
  File "/home/yalloosb/server/passenger_wsgi.py", line 1, in <module>
    from demo.wsgi import application
  File "/home/yalloosb/server/demo/wsgi.py", line 16, in <module>
    application = get_wsgi_application()
  File "/home/yalloosb/virtualenv/server/3.8/lib/python3.8/site-packages/django/core/wsgi.py", line 12, in get_wsgi_application
    django.setup(set_prefix=False)
  File "/home/yalloosb/virtualenv/server/3.8/lib/python3.8/site-packages/django/__init__.py", line 24, in setup
    apps.populate(settings.INSTALLED_APPS)
  File "/home/yalloosb/virtualenv/server/3.8/lib/python3.8/site-packages/django/apps/registry.py", line 114, in populate
    app_config.import_models()
  File "/home/yalloosb/virtualenv/server/3.8/lib/python3.8/site-packages/django/apps/config.py", line 300, in import_models
    self.models_module = import_module(models_module_name)
  File "/home/yalloosb/virtualenv/server/3.8/lib64/python3.8/importlib/__init__.py", line 127, in import_module
    return _bootstrap._gcd_import(name[level:], package, level)
  File "/home/yalloosb/virtualenv/server/3.8/lib/python3.8/site-packages/django/contrib/auth/models.py", line 3, in <module>
    from django.contrib.auth.base_user import AbstractBaseUser, BaseUserManager
  File "/home/yalloosb/virtualenv/server/3.8/lib/python3.8/site-packages/django/contrib/auth/base_user.py", line 47, in <module>
    class AbstractBaseUser(models.Model):
  File "/home/yalloosb/virtualenv/server/3.8/lib/python3.8/site-packages/django/db/models/base.py", line 122, in __new__
    new_class.add_to_class('_meta', Options(meta, app_label))
  File "/home/yalloosb/virtualenv/server/3.8/lib/python3.8/site-packages/django/db/models/base.py", line 326, in add_to_class
    value.contribute_to_class(cls, name)
  File "/home/yalloosb/virtualenv/server/3.8/lib/python3.8/site-packages/django/db/models/options.py", line 207, in contribute_to_class
    self.db_table = truncate_name(self.db_table, connection.ops.max_name_length())
  File "/home/yalloosb/virtualenv/server/3.8/lib/python3.8/site-packages/django/utils/connection.py", line 15, in __getattr__
    return getattr(self._connections[self._alias], item)
  File "/home/yalloosb/virtualenv/server/3.8/lib/python3.8/site-packages/django/utils/connection.py", line 62, in __getitem__
    conn = self.create_connection(alias)
  File "/home/yalloosb/virtualenv/server/3.8/lib/python3.8/site-packages/django/db/utils.py", line 204, in create_connection
    backend = load_backend(db['ENGINE'])
  File "/home/yalloosb/virtualenv/server/3.8/lib/python3.8/site-packages/django/db/utils.py", line 111, in load_backend
    return import_module('%s.base' % backend_name)
  File "/home/yalloosb/virtualenv/server/3.8/lib64/python3.8/importlib/__init__.py", line 127, in import_module
    return _bootstrap._gcd_import(name[level:], package, level)
  File "/home/yalloosb/virtualenv/server/3.8/lib/python3.8/site-packages/django/db/backends/mysql/base.py", line 17, in <module>
    raise ImproperlyConfigured(
django.core.exceptions.ImproperlyConfigured: Error loading MySQLdb module.
Did you install mysqlclient?
Traceback (most recent call last):
  File "/home/yalloosb/server/passenger_wsgi.py", line 1, in <module>
    from demo.wsgi import application
  File "/home/yalloosb/server/demo/wsgi.py", line 16, in <module>
    application = get_wsgi_application()
  File "/home/yalloosb/virtualenv/server/3.8/lib/python3.8/site-packages/django/core/wsgi.py", line 12, in get_wsgi_application
    django.setup(set_prefix=False)
  File "/home/yalloosb/virtualenv/server/3.8/lib/python3.8/site-packages/django/__init__.py", line 24, in setup
    apps.populate(settings.INSTALLED_APPS)
  File "/home/yalloosb/virtualenv/server/3.8/lib/python3.8/site-packages/django/apps/registry.py", line 83, in populate
    raise RuntimeError("populate() isn't reentrant")
RuntimeError: populate() isn't reentrant
Traceback (most recent call last):
  File "/home/yalloosb/server/passenger_wsgi.py", line 1, in <module>
    from demo.wsgi import application
  File "/home/yalloosb/server/demo/wsgi.py", line 16, in <module>
    application = get_wsgi_application()
  File "/home/yalloosb/virtualenv/server/3.8/lib/python3.8/site-packages/django/core/wsgi.py", line 12, in get_wsgi_application
    django.setup(set_prefix=False)
  File "/home/yalloosb/virtualenv/server/3.8/lib/python3.8/site-packages/django/__init__.py", line 24, in setup
    apps.populate(settings.INSTALLED_APPS)
  File "/home/yalloosb/virtualenv/server/3.8/lib/python3.8/site-packages/django/apps/registry.py", line 83, in populate
    raise RuntimeError("populate() isn't reentrant")
RuntimeError: populate() isn't reentrant
Traceback (most recent call last):
  File "/home/yalloosb/server/passenger_wsgi.py", line 1, in <module>
    from demo.wsgi import application
  File "/home/yalloosb/server/demo/wsgi.py", line 16, in <module>
    application = get_wsgi_application()
  File "/home/yalloosb/virtualenv/server/3.8/lib/python3.8/site-packages/django/core/wsgi.py", line 12, in get_wsgi_application
    django.setup(set_prefix=False)
  File "/home/yalloosb/virtualenv/server/3.8/lib/python3.8/site-packages/django/__init__.py", line 24, in setup
    apps.populate(settings.INSTALLED_APPS)
  File "/home/yalloosb/virtualenv/server/3.8/lib/python3.8/site-packages/django/apps/registry.py", line 83, in populate
    raise RuntimeError("populate() isn't reentrant")
RuntimeError: populate() isn't reentrant
Traceback (most recent call last):
  File "/home/yalloosb/virtualenv/server/3.8/lib/python3.8/site-packages/django/db/backends/mysql/base.py", line 15, in <module>
    import MySQLdb as Database
ModuleNotFoundError: No module named 'MySQLdb'

The above exception was the direct cause of the following exception:

Traceback (most recent call last):
  File "/home/yalloosb/server/passenger_wsgi.py", line 1, in <module>
    from demo.wsgi import application
  File "/home/yalloosb/server/demo/wsgi.py", line 16, in <module>
    application = get_wsgi_application()
  File "/home/yalloosb/virtualenv/server/3.8/lib/python3.8/site-packages/django/core/wsgi.py", line 12, in get_wsgi_application
    django.setup(set_prefix=False)
  File "/home/yalloosb/virtualenv/server/3.8/lib/python3.8/site-packages/django/__init__.py", line 24, in setup
    apps.populate(settings.INSTALLED_APPS)
  File "/home/yalloosb/virtualenv/server/3.8/lib/python3.8/site-packages/django/apps/registry.py", line 114, in populate
    app_config.import_models()
  File "/home/yalloosb/virtualenv/server/3.8/lib/python3.8/site-packages/django/apps/config.py", line 300, in import_models
    self.models_module = import_module(models_module_name)
  File "/home/yalloosb/virtualenv/server/3.8/lib64/python3.8/importlib/__init__.py", line 127, in import_module
    return _bootstrap._gcd_import(name[level:], package, level)
  File "/home/yalloosb/virtualenv/server/3.8/lib/python3.8/site-packages/django/contrib/auth/models.py", line 3, in <module>
    from django.contrib.auth.base_user import AbstractBaseUser, BaseUserManager
  File "/home/yalloosb/virtualenv/server/3.8/lib/python3.8/site-packages/django/contrib/auth/base_user.py", line 47, in <module>
    class AbstractBaseUser(models.Model):
  File "/home/yalloosb/virtualenv/server/3.8/lib/python3.8/site-packages/django/db/models/base.py", line 122, in __new__
    new_class.add_to_class('_meta', Options(meta, app_label))
  File "/home/yalloosb/virtualenv/server/3.8/lib/python3.8/site-packages/django/db/models/base.py", line 326, in add_to_class
    value.contribute_to_class(cls, name)
  File "/home/yalloosb/virtualenv/server/3.8/lib/python3.8/site-packages/django/db/models/options.py", line 207, in contribute_to_class
    self.db_table = truncate_name(self.db_table, connection.ops.max_name_length())
  File "/home/yalloosb/virtualenv/server/3.8/lib/python3.8/site-packages/django/utils/connection.py", line 15, in __getattr__
    return getattr(self._connections[self._alias], item)
  File "/home/yalloosb/virtualenv/server/3.8/lib/python3.8/site-packages/django/utils/connection.py", line 62, in __getitem__
    conn = self.create_connection(alias)
  File "/home/yalloosb/virtualenv/server/3.8/lib/python3.8/site-packages/django/db/utils.py", line 204, in create_connection
    backend = load_backend(db['ENGINE'])
  File "/home/yalloosb/virtualenv/server/3.8/lib/python3.8/site-packages/django/db/utils.py", line 111, in load_backend
    return import_module('%s.base' % backend_name)
  File "/home/yalloosb/virtualenv/server/3.8/lib64/python3.8/importlib/__init__.py", line 127, in import_module
    return _bootstrap._gcd_import(name[level:], package, level)
  File "/home/yalloosb/virtualenv/server/3.8/lib/python3.8/site-packages/django/db/backends/mysql/base.py", line 17, in <module>
    raise ImproperlyConfigured(
django.core.exceptions.ImproperlyConfigured: Error loading MySQLdb module.
Did you install mysqlclient?
Traceback (most recent call last):
  File "/home/yalloosb/server/passenger_wsgi.py", line 1, in <module>
    from demo.wsgi import application
  File "/home/yalloosb/server/demo/wsgi.py", line 16, in <module>
    application = get_wsgi_application()
  File "/home/yalloosb/virtualenv/server/3.8/lib/python3.8/site-packages/django/core/wsgi.py", line 12, in get_wsgi_application
    django.setup(set_prefix=False)
  File "/home/yalloosb/virtualenv/server/3.8/lib/python3.8/site-packages/django/__init__.py", line 24, in setup
    apps.populate(settings.INSTALLED_APPS)
  File "/home/yalloosb/virtualenv/server/3.8/lib/python3.8/site-packages/django/apps/registry.py", line 83, in populate
    raise RuntimeError("populate() isn't reentrant")
RuntimeError: populate() isn't reentrant
Traceback (most recent call last):
  File "/home/yalloosb/server/passenger_wsgi.py", line 1, in <module>
    from demo.wsgi import application
  File "/home/yalloosb/server/demo/wsgi.py", line 16, in <module>
    application = get_wsgi_application()
  File "/home/yalloosb/virtualenv/server/3.8/lib/python3.8/site-packages/django/core/wsgi.py", line 12, in get_wsgi_application
    django.setup(set_prefix=False)
  File "/home/yalloosb/virtualenv/server/3.8/lib/python3.8/site-packages/django/__init__.py", line 24, in setup
    apps.populate(settings.INSTALLED_APPS)
  File "/home/yalloosb/virtualenv/server/3.8/lib/python3.8/site-packages/django/apps/registry.py", line 83, in populate
    raise RuntimeError("populate() isn't reentrant")
RuntimeError: populate() isn't reentrant
Traceback (most recent call last):
  File "/home/yalloosb/server/passenger_wsgi.py", line 1, in <module>
    from demo.wsgi import application
  File "/home/yalloosb/server/demo/wsgi.py", line 16, in <module>
    application = get_wsgi_application()
  File "/home/yalloosb/virtualenv/server/3.8/lib/python3.8/site-packages/django/core/wsgi.py", line 12, in get_wsgi_application
    django.setup(set_prefix=False)
  File "/home/yalloosb/virtualenv/server/3.8/lib/python3.8/site-packages/django/__init__.py", line 24, in setup
    apps.populate(settings.INSTALLED_APPS)
  File "/home/yalloosb/virtualenv/server/3.8/lib/python3.8/site-packages/django/apps/registry.py", line 83, in populate
    raise RuntimeError("populate() isn't reentrant")
RuntimeError: populate() isn't reentrant
Traceback (most recent call last):
  File "/home/yalloosb/server/passenger_wsgi.py", line 1, in <module>
    from demo.wsgi import application
  File "/home/yalloosb/server/demo/wsgi.py", line 16, in <module>
    application = get_wsgi_application()
  File "/home/yalloosb/virtualenv/server/3.8/lib/python3.8/site-packages/django/core/wsgi.py", line 12, in get_wsgi_application
    django.setup(set_prefix=False)
  File "/home/yalloosb/virtualenv/server/3.8/lib/python3.8/site-packages/django/__init__.py", line 24, in setup
    apps.populate(settings.INSTALLED_APPS)
  File "/home/yalloosb/virtualenv/server/3.8/lib/python3.8/site-packages/django/apps/registry.py", line 83, in populate
    raise RuntimeError("populate() isn't reentrant")
RuntimeError: populate() isn't reentrant
Traceback (most recent call last):
  File "/home/yalloosb/virtualenv/server/3.8/lib/python3.8/site-packages/django/db/backends/mysql/base.py", line 15, in <module>
    import MySQLdb as Database
ModuleNotFoundError: No module named 'MySQLdb'

The above exception was the direct cause of the following exception:

Traceback (most recent call last):
  File "/home/yalloosb/server/passenger_wsgi.py", line 1, in <module>
    from demo.wsgi import application
  File "/home/yalloosb/server/demo/wsgi.py", line 16, in <module>
    application = get_wsgi_application()
  File "/home/yalloosb/virtualenv/server/3.8/lib/python3.8/site-packages/django/core/wsgi.py", line 12, in get_wsgi_application
    django.setup(set_prefix=False)
  File "/home/yalloosb/virtualenv/server/3.8/lib/python3.8/site-packages/django/__init__.py", line 24, in setup
    apps.populate(settings.INSTALLED_APPS)
  File "/home/yalloosb/virtualenv/server/3.8/lib/python3.8/site-packages/django/apps/registry.py", line 114, in populate
    app_config.import_models()
  File "/home/yalloosb/virtualenv/server/3.8/lib/python3.8/site-packages/django/apps/config.py", line 300, in import_models
    self.models_module = import_module(models_module_name)
  File "/home/yalloosb/virtualenv/server/3.8/lib64/python3.8/importlib/__init__.py", line 127, in import_module
    return _bootstrap._gcd_import(name[level:], package, level)
  File "/home/yalloosb/virtualenv/server/3.8/lib/python3.8/site-packages/django/contrib/auth/models.py", line 3, in <module>
    from django.contrib.auth.base_user import AbstractBaseUser, BaseUserManager
  File "/home/yalloosb/virtualenv/server/3.8/lib/python3.8/site-packages/django/contrib/auth/base_user.py", line 47, in <module>
    class AbstractBaseUser(models.Model):
  File "/home/yalloosb/virtualenv/server/3.8/lib/python3.8/site-packages/django/db/models/base.py", line 122, in __new__
    new_class.add_to_class('_meta', Options(meta, app_label))
  File "/home/yalloosb/virtualenv/server/3.8/lib/python3.8/site-packages/django/db/models/base.py", line 326, in add_to_class
    value.contribute_to_class(cls, name)
  File "/home/yalloosb/virtualenv/server/3.8/lib/python3.8/site-packages/django/db/models/options.py", line 207, in contribute_to_class
    self.db_table = truncate_name(self.db_table, connection.ops.max_name_length())
  File "/home/yalloosb/virtualenv/server/3.8/lib/python3.8/site-packages/django/utils/connection.py", line 15, in __getattr__
    return getattr(self._connections[self._alias], item)
  File "/home/yalloosb/virtualenv/server/3.8/lib/python3.8/site-packages/django/utils/connection.py", line 62, in __getitem__
    conn = self.create_connection(alias)
  File "/home/yalloosb/virtualenv/server/3.8/lib/python3.8/site-packages/django/db/utils.py", line 204, in create_connection
    backend = load_backend(db['ENGINE'])
  File "/home/yalloosb/virtualenv/server/3.8/lib/python3.8/site-packages/django/db/utils.py", line 111, in load_backend
    return import_module('%s.base' % backend_name)
  File "/home/yalloosb/virtualenv/server/3.8/lib64/python3.8/importlib/__init__.py", line 127, in import_module
    return _bootstrap._gcd_import(name[level:], package, level)
  File "/home/yalloosb/virtualenv/server/3.8/lib/python3.8/site-packages/django/db/backends/mysql/base.py", line 17, in <module>
    raise ImproperlyConfigured(
django.core.exceptions.ImproperlyConfigured: Error loading MySQLdb module.
Did you install mysqlclient?
Traceback (most recent call last):
  File "/home/yalloosb/server/passenger_wsgi.py", line 1, in <module>
    from demo.wsgi import application
  File "/home/yalloosb/server/demo/wsgi.py", line 16, in <module>
    application = get_wsgi_application()
  File "/home/yalloosb/virtualenv/server/3.8/lib/python3.8/site-packages/django/core/wsgi.py", line 12, in get_wsgi_application
    django.setup(set_prefix=False)
  File "/home/yalloosb/virtualenv/server/3.8/lib/python3.8/site-packages/django/__init__.py", line 24, in setup
    apps.populate(settings.INSTALLED_APPS)
  File "/home/yalloosb/virtualenv/server/3.8/lib/python3.8/site-packages/django/apps/registry.py", line 83, in populate
    raise RuntimeError("populate() isn't reentrant")
RuntimeError: populate() isn't reentrant
Traceback (most recent call last):
  File "/home/yalloosb/server/passenger_wsgi.py", line 1, in <module>
    from demo.wsgi import application
  File "/home/yalloosb/server/demo/wsgi.py", line 16, in <module>
    application = get_wsgi_application()
  File "/home/yalloosb/virtualenv/server/3.8/lib/python3.8/site-packages/django/core/wsgi.py", line 12, in get_wsgi_application
    django.setup(set_prefix=False)
  File "/home/yalloosb/virtualenv/server/3.8/lib/python3.8/site-packages/django/__init__.py", line 24, in setup
    apps.populate(settings.INSTALLED_APPS)
  File "/home/yalloosb/virtualenv/server/3.8/lib/python3.8/site-packages/django/apps/registry.py", line 83, in populate
    raise RuntimeError("populate() isn't reentrant")
RuntimeError: populate() isn't reentrant
Traceback (most recent call last):
  File "/home/yalloosb/server/passenger_wsgi.py", line 1, in <module>
    from demo.wsgi import application
  File "/home/yalloosb/server/demo/wsgi.py", line 16, in <module>
    application = get_wsgi_application()
  File "/home/yalloosb/virtualenv/server/3.8/lib/python3.8/site-packages/django/core/wsgi.py", line 12, in get_wsgi_application
    django.setup(set_prefix=False)
  File "/home/yalloosb/virtualenv/server/3.8/lib/python3.8/site-packages/django/__init__.py", line 24, in setup
    apps.populate(settings.INSTALLED_APPS)
  File "/home/yalloosb/virtualenv/server/3.8/lib/python3.8/site-packages/django/apps/registry.py", line 83, in populate
    raise RuntimeError("populate() isn't reentrant")
RuntimeError: populate() isn't reentrant
Traceback (most recent call last):
  File "/home/yalloosb/server/passenger_wsgi.py", line 1, in <module>
    from demo.wsgi import application
  File "/home/yalloosb/server/demo/wsgi.py", line 16, in <module>
    application = get_wsgi_application()
  File "/home/yalloosb/virtualenv/server/3.8/lib/python3.8/site-packages/django/core/wsgi.py", line 12, in get_wsgi_application
    django.setup(set_prefix=False)
  File "/home/yalloosb/virtualenv/server/3.8/lib/python3.8/site-packages/django/__init__.py", line 24, in setup
    apps.populate(settings.INSTALLED_APPS)
  File "/home/yalloosb/virtualenv/server/3.8/lib/python3.8/site-packages/django/apps/registry.py", line 83, in populate
    raise RuntimeError("populate() isn't reentrant")
RuntimeError: populate() isn't reentrant
Traceback (most recent call last):
  File "/home/yalloosb/server/passenger_wsgi.py", line 1, in <module>
    from demo.wsgi import application
  File "/home/yalloosb/server/demo/wsgi.py", line 16, in <module>
    application = get_wsgi_application()
  File "/home/yalloosb/virtualenv/server/3.8/lib/python3.8/site-packages/django/core/wsgi.py", line 12, in get_wsgi_application
    django.setup(set_prefix=False)
  File "/home/yalloosb/virtualenv/server/3.8/lib/python3.8/site-packages/django/__init__.py", line 24, in setup
    apps.populate(settings.INSTALLED_APPS)
  File "/home/yalloosb/virtualenv/server/3.8/lib/python3.8/site-packages/django/apps/registry.py", line 83, in populate
    raise RuntimeError("populate() isn't reentrant")
RuntimeError: populate() isn't reentrant
Traceback (most recent call last):
  File "/home/yalloosb/server/passenger_wsgi.py", line 1, in <module>
    from demo.wsgi import application
  File "/home/yalloosb/server/demo/wsgi.py", line 16, in <module>
    application = get_wsgi_application()
  File "/home/yalloosb/virtualenv/server/3.8/lib/python3.8/site-packages/django/core/wsgi.py", line 12, in get_wsgi_application
    django.setup(set_prefix=False)
  File "/home/yalloosb/virtualenv/server/3.8/lib/python3.8/site-packages/django/__init__.py", line 24, in setup
    apps.populate(settings.INSTALLED_APPS)
  File "/home/yalloosb/virtualenv/server/3.8/lib/python3.8/site-packages/django/apps/registry.py", line 83, in populate
    raise RuntimeError("populate() isn't reentrant")
RuntimeError: populate() isn't reentrant
Traceback (most recent call last):
  File "/home/yalloosb/virtualenv/server/3.8/lib/python3.8/site-packages/django/db/backends/mysql/base.py", line 15, in <module>
    import MySQLdb as Database
ModuleNotFoundError: No module named 'MySQLdb'

The above exception was the direct cause of the following exception:

Traceback (most recent call last):
  File "/home/yalloosb/server/passenger_wsgi.py", line 1, in <module>
    from demo.wsgi import application
  File "/home/yalloosb/server/demo/wsgi.py", line 16, in <module>
    application = get_wsgi_application()
  File "/home/yalloosb/virtualenv/server/3.8/lib/python3.8/site-packages/django/core/wsgi.py", line 12, in get_wsgi_application
    django.setup(set_prefix=False)
  File "/home/yalloosb/virtualenv/server/3.8/lib/python3.8/site-packages/django/__init__.py", line 24, in setup
    apps.populate(settings.INSTALLED_APPS)
  File "/home/yalloosb/virtualenv/server/3.8/lib/python3.8/site-packages/django/apps/registry.py", line 114, in populate
    app_config.import_models()
  File "/home/yalloosb/virtualenv/server/3.8/lib/python3.8/site-packages/django/apps/config.py", line 300, in import_models
    self.models_module = import_module(models_module_name)
  File "/home/yalloosb/virtualenv/server/3.8/lib64/python3.8/importlib/__init__.py", line 127, in import_module
    return _bootstrap._gcd_import(name[level:], package, level)
  File "/home/yalloosb/virtualenv/server/3.8/lib/python3.8/site-packages/django/contrib/auth/models.py", line 3, in <module>
    from django.contrib.auth.base_user import AbstractBaseUser, BaseUserManager
  File "/home/yalloosb/virtualenv/server/3.8/lib/python3.8/site-packages/django/contrib/auth/base_user.py", line 47, in <module>
    class AbstractBaseUser(models.Model):
  File "/home/yalloosb/virtualenv/server/3.8/lib/python3.8/site-packages/django/db/models/base.py", line 122, in __new__
    new_class.add_to_class('_meta', Options(meta, app_label))
  File "/home/yalloosb/virtualenv/server/3.8/lib/python3.8/site-packages/django/db/models/base.py", line 326, in add_to_class
    value.contribute_to_class(cls, name)
  File "/home/yalloosb/virtualenv/server/3.8/lib/python3.8/site-packages/django/db/models/options.py", line 207, in contribute_to_class
    self.db_table = truncate_name(self.db_table, connection.ops.max_name_length())
  File "/home/yalloosb/virtualenv/server/3.8/lib/python3.8/site-packages/django/utils/connection.py", line 15, in __getattr__
    return getattr(self._connections[self._alias], item)
  File "/home/yalloosb/virtualenv/server/3.8/lib/python3.8/site-packages/django/utils/connection.py", line 62, in __getitem__
    conn = self.create_connection(alias)
  File "/home/yalloosb/virtualenv/server/3.8/lib/python3.8/site-packages/django/db/utils.py", line 204, in create_connection
    backend = load_backend(db['ENGINE'])
  File "/home/yalloosb/virtualenv/server/3.8/lib/python3.8/site-packages/django/db/utils.py", line 111, in load_backend
    return import_module('%s.base' % backend_name)
  File "/home/yalloosb/virtualenv/server/3.8/lib64/python3.8/importlib/__init__.py", line 127, in import_module
    return _bootstrap._gcd_import(name[level:], package, level)
  File "/home/yalloosb/virtualenv/server/3.8/lib/python3.8/site-packages/django/db/backends/mysql/base.py", line 17, in <module>
    raise ImproperlyConfigured(
django.core.exceptions.ImproperlyConfigured: Error loading MySQLdb module.
Did you install mysqlclient?
Traceback (most recent call last):
  File "/home/yalloosb/server/passenger_wsgi.py", line 1, in <module>
    from demo.wsgi import application
  File "/home/yalloosb/server/demo/wsgi.py", line 16, in <module>
    application = get_wsgi_application()
  File "/home/yalloosb/virtualenv/server/3.8/lib/python3.8/site-packages/django/core/wsgi.py", line 12, in get_wsgi_application
    django.setup(set_prefix=False)
  File "/home/yalloosb/virtualenv/server/3.8/lib/python3.8/site-packages/django/__init__.py", line 24, in setup
    apps.populate(settings.INSTALLED_APPS)
  File "/home/yalloosb/virtualenv/server/3.8/lib/python3.8/site-packages/django/apps/registry.py", line 83, in populate
    raise RuntimeError("populate() isn't reentrant")
RuntimeError: populate() isn't reentrant
Traceback (most recent call last):
  File "/home/yalloosb/server/passenger_wsgi.py", line 1, in <module>
    from demo.wsgi import application
  File "/home/yalloosb/server/demo/wsgi.py", line 16, in <module>
    application = get_wsgi_application()
  File "/home/yalloosb/virtualenv/server/3.8/lib/python3.8/site-packages/django/core/wsgi.py", line 12, in get_wsgi_application
    django.setup(set_prefix=False)
  File "/home/yalloosb/virtualenv/server/3.8/lib/python3.8/site-packages/django/__init__.py", line 24, in setup
    apps.populate(settings.INSTALLED_APPS)
  File "/home/yalloosb/virtualenv/server/3.8/lib/python3.8/site-packages/django/apps/registry.py", line 83, in populate
    raise RuntimeError("populate() isn't reentrant")
RuntimeError: populate() isn't reentrant
Traceback (most recent call last):
  File "/home/yalloosb/server/passenger_wsgi.py", line 1, in <module>
    from demo.wsgi import application
  File "/home/yalloosb/server/demo/wsgi.py", line 16, in <module>
    application = get_wsgi_application()
  File "/home/yalloosb/virtualenv/server/3.8/lib/python3.8/site-packages/django/core/wsgi.py", line 12, in get_wsgi_application
    django.setup(set_prefix=False)
  File "/home/yalloosb/virtualenv/server/3.8/lib/python3.8/site-packages/django/__init__.py", line 24, in setup
    apps.populate(settings.INSTALLED_APPS)
  File "/home/yalloosb/virtualenv/server/3.8/lib/python3.8/site-packages/django/apps/registry.py", line 83, in populate
    raise RuntimeError("populate() isn't reentrant")
RuntimeError: populate() isn't reentrant
Traceback (most recent call last):
  File "/home/yalloosb/server/passenger_wsgi.py", line 1, in <module>
    from demo.wsgi import application
  File "/home/yalloosb/server/demo/wsgi.py", line 16, in <module>
    application = get_wsgi_application()
  File "/home/yalloosb/virtualenv/server/3.8/lib/python3.8/site-packages/django/core/wsgi.py", line 12, in get_wsgi_application
    django.setup(set_prefix=False)
  File "/home/yalloosb/virtualenv/server/3.8/lib/python3.8/site-packages/django/__init__.py", line 24, in setup
    apps.populate(settings.INSTALLED_APPS)
  File "/home/yalloosb/virtualenv/server/3.8/lib/python3.8/site-packages/django/apps/registry.py", line 83, in populate
    raise RuntimeError("populate() isn't reentrant")
RuntimeError: populate() isn't reentrant
Traceback (most recent call last):
  File "/home/yalloosb/server/passenger_wsgi.py", line 1, in <module>
    from demo.wsgi import application
  File "/home/yalloosb/server/demo/wsgi.py", line 16, in <module>
    application = get_wsgi_application()
  File "/home/yalloosb/virtualenv/server/3.8/lib/python3.8/site-packages/django/core/wsgi.py", line 12, in get_wsgi_application
    django.setup(set_prefix=False)
  File "/home/yalloosb/virtualenv/server/3.8/lib/python3.8/site-packages/django/__init__.py", line 24, in setup
    apps.populate(settings.INSTALLED_APPS)
  File "/home/yalloosb/virtualenv/server/3.8/lib/python3.8/site-packages/django/apps/registry.py", line 83, in populate
    raise RuntimeError("populate() isn't reentrant")
RuntimeError: populate() isn't reentrant
Traceback (most recent call last):
  File "/home/yalloosb/server/passenger_wsgi.py", line 1, in <module>
    from demo.wsgi import application
  File "/home/yalloosb/server/demo/wsgi.py", line 16, in <module>
    application = get_wsgi_application()
  File "/home/yalloosb/virtualenv/server/3.8/lib/python3.8/site-packages/django/core/wsgi.py", line 12, in get_wsgi_application
    django.setup(set_prefix=False)
  File "/home/yalloosb/virtualenv/server/3.8/lib/python3.8/site-packages/django/__init__.py", line 24, in setup
    apps.populate(settings.INSTALLED_APPS)
  File "/home/yalloosb/virtualenv/server/3.8/lib/python3.8/site-packages/django/apps/registry.py", line 83, in populate
    raise RuntimeError("populate() isn't reentrant")
RuntimeError: populate() isn't reentrant
Traceback (most recent call last):
  File "/home/yalloosb/server/passenger_wsgi.py", line 1, in <module>
    from demo.wsgi import application
  File "/home/yalloosb/server/demo/wsgi.py", line 16, in <module>
    application = get_wsgi_application()
  File "/home/yalloosb/virtualenv/server/3.8/lib/python3.8/site-packages/django/core/wsgi.py", line 12, in get_wsgi_application
    django.setup(set_prefix=False)
  File "/home/yalloosb/virtualenv/server/3.8/lib/python3.8/site-packages/django/__init__.py", line 24, in setup
    apps.populate(settings.INSTALLED_APPS)
  File "/home/yalloosb/virtualenv/server/3.8/lib/python3.8/site-packages/django/apps/registry.py", line 83, in populate
    raise RuntimeError("populate() isn't reentrant")
RuntimeError: populate() isn't reentrant
Traceback (most recent call last):
  File "/home/yalloosb/server/passenger_wsgi.py", line 1, in <module>
    from demo.wsgi import application
  File "/home/yalloosb/server/demo/wsgi.py", line 16, in <module>
    application = get_wsgi_application()
  File "/home/yalloosb/virtualenv/server/3.8/lib/python3.8/site-packages/django/core/wsgi.py", line 12, in get_wsgi_application
    django.setup(set_prefix=False)
  File "/home/yalloosb/virtualenv/server/3.8/lib/python3.8/site-packages/django/__init__.py", line 24, in setup
    apps.populate(settings.INSTALLED_APPS)
  File "/home/yalloosb/virtualenv/server/3.8/lib/python3.8/site-packages/django/apps/registry.py", line 83, in populate
    raise RuntimeError("populate() isn't reentrant")
RuntimeError: populate() isn't reentrant
Traceback (most recent call last):
  File "/home/yalloosb/server/passenger_wsgi.py", line 1, in <module>
    from demo.wsgi import application
  File "/home/yalloosb/server/demo/wsgi.py", line 16, in <module>
    application = get_wsgi_application()
  File "/home/yalloosb/virtualenv/server/3.8/lib/python3.8/site-packages/django/core/wsgi.py", line 12, in get_wsgi_application
    django.setup(set_prefix=False)
  File "/home/yalloosb/virtualenv/server/3.8/lib/python3.8/site-packages/django/__init__.py", line 24, in setup
    apps.populate(settings.INSTALLED_APPS)
  File "/home/yalloosb/virtualenv/server/3.8/lib/python3.8/site-packages/django/apps/registry.py", line 83, in populate
    raise RuntimeError("populate() isn't reentrant")
RuntimeError: populate() isn't reentrant
Traceback (most recent call last):
  File "/home/yalloosb/server/passenger_wsgi.py", line 1, in <module>
    from demo.wsgi import application
  File "/home/yalloosb/server/demo/wsgi.py", line 16, in <module>
    application = get_wsgi_application()
  File "/home/yalloosb/virtualenv/server/3.8/lib/python3.8/site-packages/django/core/wsgi.py", line 12, in get_wsgi_application
    django.setup(set_prefix=False)
  File "/home/yalloosb/virtualenv/server/3.8/lib/python3.8/site-packages/django/__init__.py", line 24, in setup
    apps.populate(settings.INSTALLED_APPS)
  File "/home/yalloosb/virtualenv/server/3.8/lib/python3.8/site-packages/django/apps/registry.py", line 83, in populate
    raise RuntimeError("populate() isn't reentrant")
RuntimeError: populate() isn't reentrant
Traceback (most recent call last):
  File "/home/yalloosb/server/passenger_wsgi.py", line 1, in <module>
    from demo.wsgi import application
  File "/home/yalloosb/server/demo/wsgi.py", line 16, in <module>
    application = get_wsgi_application()
  File "/home/yalloosb/virtualenv/server/3.8/lib/python3.8/site-packages/django/core/wsgi.py", line 12, in get_wsgi_application
    django.setup(set_prefix=False)
  File "/home/yalloosb/virtualenv/server/3.8/lib/python3.8/site-packages/django/__init__.py", line 24, in setup
    apps.populate(settings.INSTALLED_APPS)
  File "/home/yalloosb/virtualenv/server/3.8/lib/python3.8/site-packages/django/apps/registry.py", line 83, in populate
    raise RuntimeError("populate() isn't reentrant")
RuntimeError: populate() isn't reentrant
[UID:632][2578967] Child process with pid: 2579008 was killed by signal: 9, core dump: 0
Not Found: /adminl
[UID:632][3022300] Child process with pid: 3022333 was killed by signal: 9, core dump: 0
[UID:632][3144206] Child process with pid: 3144214 was killed by signal: 9, core dump: 0
